[2025-07-03T04:36:29.573+0000] {local_task_job_runner.py:120} INFO - ::group::Pre task execution logs
[2025-07-03T04:36:29.594+0000] {taskinstance.py:2076} INFO - Dependencies all met for dep_context=non-requeueable deps ti=<TaskInstance: ocr_logging_analysis_dag.upload_files_to_s3 scheduled__2025-07-02T00:00:00+00:00 [queued]>
[2025-07-03T04:36:29.599+0000] {taskinstance.py:2076} INFO - Dependencies all met for dep_context=requeueable deps ti=<TaskInstance: ocr_logging_analysis_dag.upload_files_to_s3 scheduled__2025-07-02T00:00:00+00:00 [queued]>
[2025-07-03T04:36:29.600+0000] {taskinstance.py:2306} INFO - Starting attempt 1 of 1
[2025-07-03T04:36:29.614+0000] {taskinstance.py:2330} INFO - Executing <Task(PythonOperator): upload_files_to_s3> on 2025-07-02 00:00:00+00:00
[2025-07-03T04:36:29.620+0000] {standard_task_runner.py:63} INFO - Started process 21380 to run task
[2025-07-03T04:36:29.623+0000] {standard_task_runner.py:90} INFO - Running: ['airflow', 'tasks', 'run', 'ocr_logging_analysis_dag', 'upload_files_to_s3', 'scheduled__2025-07-02T00:00:00+00:00', '--job-id', '2', '--raw', '--subdir', 'DAGS_FOLDER/ocr_gateway_log_dag.py', '--cfg-path', '/tmp/tmp5wmmgwn7']
[2025-07-03T04:36:29.624+0000] {standard_task_runner.py:91} INFO - Job 2: Subtask upload_files_to_s3
[2025-07-03T04:36:29.660+0000] {task_command.py:426} INFO - Running <TaskInstance: ocr_logging_analysis_dag.upload_files_to_s3 scheduled__2025-07-02T00:00:00+00:00 [running]> on host ip-172-31-12-43.ap-northeast-2.compute.internal
[2025-07-03T04:36:29.715+0000] {taskinstance.py:2648} INFO - Exporting env vars: AIRFLOW_CTX_DAG_OWNER='airflow' AIRFLOW_CTX_DAG_ID='ocr_logging_analysis_dag' AIRFLOW_CTX_TASK_ID='upload_files_to_s3' AIRFLOW_CTX_EXECUTION_DATE='2025-07-02T00:00:00+00:00' AIRFLOW_CTX_TRY_NUMBER='1' AIRFLOW_CTX_DAG_RUN_ID='scheduled__2025-07-02T00:00:00+00:00'
[2025-07-03T04:36:29.716+0000] {taskinstance.py:430} INFO - ::endgroup::
[2025-07-03T04:36:30.550+0000] {taskinstance.py:441} INFO - ::group::Post task execution logs
[2025-07-03T04:36:30.551+0000] {taskinstance.py:2905} ERROR - Task failed with exception
Traceback (most recent call last):
  File "/home/ubuntu/miniconda3/envs/OCR_Gateway_Airflow/lib/python3.11/site-packages/airflow/models/taskinstance.py", line 465, in _execute_task
    result = _execute_callable(context=context, **execute_callable_kwargs)
             ^^^^^^^^^^^^^^^^^^^^^^^^^^^^^^^^^^^^^^^^^^^^^^^^^^^^^^^^^^^^^
  File "/home/ubuntu/miniconda3/envs/OCR_Gateway_Airflow/lib/python3.11/site-packages/airflow/models/taskinstance.py", line 432, in _execute_callable
    return execute_callable(context=context, **execute_callable_kwargs)
           ^^^^^^^^^^^^^^^^^^^^^^^^^^^^^^^^^^^^^^^^^^^^^^^^^^^^^^^^^^^^
  File "/home/ubuntu/miniconda3/envs/OCR_Gateway_Airflow/lib/python3.11/site-packages/airflow/models/baseoperator.py", line 400, in wrapper
    return func(self, *args, **kwargs)
           ^^^^^^^^^^^^^^^^^^^^^^^^^^^
  File "/home/ubuntu/miniconda3/envs/OCR_Gateway_Airflow/lib/python3.11/site-packages/airflow/operators/python.py", line 235, in execute
    return_value = self.execute_callable()
                   ^^^^^^^^^^^^^^^^^^^^^^^
  File "/home/ubuntu/miniconda3/envs/OCR_Gateway_Airflow/lib/python3.11/site-packages/airflow/operators/python.py", line 252, in execute_callable
    return self.python_callable(*self.op_args, **self.op_kwargs)
           ^^^^^^^^^^^^^^^^^^^^^^^^^^^^^^^^^^^^^^^^^^^^^^^^^^^^^
  File "/home/ubuntu/OCR_Gateway/airflow/dags/ocr_gateway_log_dag.py", line 52, in upload_files_to_s3
    raise AirflowFailException(f"Upload failed for: {failed}")
airflow.exceptions.AirflowFailException: Upload failed for: ['2025-07-02T07-06-21Z_HiNAS_2095f68e-79d1-498f-adba-6cc70c01c465.json', '2025-07-02T07-05-55Z_HiNAS_581945b9-a6c8-4cb5-a565-50cf3581473a.json']
[2025-07-03T04:36:30.555+0000] {taskinstance.py:1206} INFO - Immediate failure requested. Marking task as FAILED. dag_id=ocr_logging_analysis_dag, task_id=upload_files_to_s3, run_id=scheduled__2025-07-02T00:00:00+00:00, execution_date=20250702T000000, start_date=20250703T043629, end_date=20250703T043630
[2025-07-03T04:36:30.562+0000] {logging_mixin.py:188} WARNING - /home/ubuntu/miniconda3/envs/OCR_Gateway_Airflow/lib/python3.11/site-packages/airflow/utils/email.py:154 RemovedInAirflow3Warning: Fetching SMTP credentials from configuration variables will be deprecated in a future release. Please set credentials using a connection instead.
[2025-07-03T04:36:30.562+0000] {configuration.py:1050} WARNING - section/key [smtp/smtp_user] not found in config
[2025-07-03T04:36:30.562+0000] {email.py:271} INFO - Email alerting: attempt 1
[2025-07-03T04:36:30.563+0000] {taskinstance.py:1182} ERROR - Error when executing send_failure_email callback
Traceback (most recent call last):
  File "/home/ubuntu/miniconda3/envs/OCR_Gateway_Airflow/lib/python3.11/site-packages/airflow/models/taskinstance.py", line 2479, in _run_raw_task
    self._execute_task_with_callbacks(context, test_mode, session=session)
  File "/home/ubuntu/miniconda3/envs/OCR_Gateway_Airflow/lib/python3.11/site-packages/airflow/models/taskinstance.py", line 2676, in _execute_task_with_callbacks
    result = self._execute_task(context, task_orig)
             ^^^^^^^^^^^^^^^^^^^^^^^^^^^^^^^^^^^^^^
  File "/home/ubuntu/miniconda3/envs/OCR_Gateway_Airflow/lib/python3.11/site-packages/airflow/models/taskinstance.py", line 2701, in _execute_task
    return _execute_task(self, context, task_orig)
           ^^^^^^^^^^^^^^^^^^^^^^^^^^^^^^^^^^^^^^^
  File "/home/ubuntu/miniconda3/envs/OCR_Gateway_Airflow/lib/python3.11/site-packages/airflow/models/taskinstance.py", line 465, in _execute_task
    result = _execute_callable(context=context, **execute_callable_kwargs)
             ^^^^^^^^^^^^^^^^^^^^^^^^^^^^^^^^^^^^^^^^^^^^^^^^^^^^^^^^^^^^^
  File "/home/ubuntu/miniconda3/envs/OCR_Gateway_Airflow/lib/python3.11/site-packages/airflow/models/taskinstance.py", line 432, in _execute_callable
    return execute_callable(context=context, **execute_callable_kwargs)
           ^^^^^^^^^^^^^^^^^^^^^^^^^^^^^^^^^^^^^^^^^^^^^^^^^^^^^^^^^^^^
  File "/home/ubuntu/miniconda3/envs/OCR_Gateway_Airflow/lib/python3.11/site-packages/airflow/models/baseoperator.py", line 400, in wrapper
    return func(self, *args, **kwargs)
           ^^^^^^^^^^^^^^^^^^^^^^^^^^^
  File "/home/ubuntu/miniconda3/envs/OCR_Gateway_Airflow/lib/python3.11/site-packages/airflow/operators/python.py", line 235, in execute
    return_value = self.execute_callable()
                   ^^^^^^^^^^^^^^^^^^^^^^^
  File "/home/ubuntu/miniconda3/envs/OCR_Gateway_Airflow/lib/python3.11/site-packages/airflow/operators/python.py", line 252, in execute_callable
    return self.python_callable(*self.op_args, **self.op_kwargs)
           ^^^^^^^^^^^^^^^^^^^^^^^^^^^^^^^^^^^^^^^^^^^^^^^^^^^^^
  File "/home/ubuntu/OCR_Gateway/airflow/dags/ocr_gateway_log_dag.py", line 52, in upload_files_to_s3
    raise AirflowFailException(f"Upload failed for: {failed}")
airflow.exceptions.AirflowFailException: Upload failed for: ['2025-07-02T07-06-21Z_HiNAS_2095f68e-79d1-498f-adba-6cc70c01c465.json', '2025-07-02T07-05-55Z_HiNAS_581945b9-a6c8-4cb5-a565-50cf3581473a.json']

During handling of the above exception, another exception occurred:

Traceback (most recent call last):
  File "/home/ubuntu/miniconda3/envs/OCR_Gateway_Airflow/lib/python3.11/site-packages/airflow/models/taskinstance.py", line 1179, in _run_finished_callback
    callback(context)
  File "/home/ubuntu/OCR_Gateway/airflow/dags/ocr_gateway_log_dag.py", line 62, in send_failure_email
    send_email(
  File "/home/ubuntu/miniconda3/envs/OCR_Gateway_Airflow/lib/python3.11/site-packages/airflow/utils/email.py", line 80, in send_email
    return backend(
           ^^^^^^^^
  File "/home/ubuntu/miniconda3/envs/OCR_Gateway_Airflow/lib/python3.11/site-packages/airflow/utils/email.py", line 154, in send_email_smtp
    send_mime_email(e_from=mail_from, e_to=recipients, mime_msg=msg, conn_id=conn_id, dryrun=dryrun)
  File "/home/ubuntu/miniconda3/envs/OCR_Gateway_Airflow/lib/python3.11/site-packages/airflow/utils/email.py", line 273, in send_mime_email
    smtp_conn = _get_smtp_connection(smtp_host, smtp_port, smtp_timeout, smtp_ssl)
                ^^^^^^^^^^^^^^^^^^^^^^^^^^^^^^^^^^^^^^^^^^^^^^^^^^^^^^^^^^^^^^^^^^
  File "/home/ubuntu/miniconda3/envs/OCR_Gateway_Airflow/lib/python3.11/site-packages/airflow/utils/email.py", line 317, in _get_smtp_connection
    return smtplib.SMTP(host=host, port=port, timeout=timeout)
           ^^^^^^^^^^^^^^^^^^^^^^^^^^^^^^^^^^^^^^^^^^^^^^^^^^^
  File "/home/ubuntu/miniconda3/envs/OCR_Gateway_Airflow/lib/python3.11/smtplib.py", line 255, in __init__
    (code, msg) = self.connect(host, port)
                  ^^^^^^^^^^^^^^^^^^^^^^^^
  File "/home/ubuntu/miniconda3/envs/OCR_Gateway_Airflow/lib/python3.11/smtplib.py", line 341, in connect
    self.sock = self._get_socket(host, port, self.timeout)
                ^^^^^^^^^^^^^^^^^^^^^^^^^^^^^^^^^^^^^^^^^^
  File "/home/ubuntu/miniconda3/envs/OCR_Gateway_Airflow/lib/python3.11/smtplib.py", line 312, in _get_socket
    return socket.create_connection((host, port), timeout,
           ^^^^^^^^^^^^^^^^^^^^^^^^^^^^^^^^^^^^^^^^^^^^^^^
  File "/home/ubuntu/miniconda3/envs/OCR_Gateway_Airflow/lib/python3.11/socket.py", line 863, in create_connection
    raise exceptions[0]
  File "/home/ubuntu/miniconda3/envs/OCR_Gateway_Airflow/lib/python3.11/socket.py", line 848, in create_connection
    sock.connect(sa)
ConnectionRefusedError: [Errno 111] Connection refused
[2025-07-03T04:36:30.579+0000] {standard_task_runner.py:110} ERROR - Failed to execute job 2 for task upload_files_to_s3 (Upload failed for: ['2025-07-02T07-06-21Z_HiNAS_2095f68e-79d1-498f-adba-6cc70c01c465.json', '2025-07-02T07-05-55Z_HiNAS_581945b9-a6c8-4cb5-a565-50cf3581473a.json']; 21380)
[2025-07-03T04:36:30.598+0000] {local_task_job_runner.py:240} INFO - Task exited with return code 1
[2025-07-03T04:36:30.613+0000] {taskinstance.py:3498} INFO - 0 downstream tasks scheduled from follow-on schedule check
[2025-07-03T04:36:30.621+0000] {local_task_job_runner.py:222} INFO - ::endgroup::
